2019-08-07 13:19:48,608 - Client_Library - ERROR - Refresh token not provided!; Exception Message::Error occurred for https://www.zohoapis.com/crm/v2/Leads/4119895000000229431. Error Code: 0 Response error_content: None. Error Details::['  File "/home/nimish/Downloads/pycharm-community-2017.3.2/helpers/pydev/pydevconsole.py", line 517, in <module>\n    pydevconsole.start_server(host, int(port), int(client_port), client_host)\n', '  File "/home/nimish/Downloads/pycharm-community-2017.3.2/helpers/pydev/pydevconsole.py", line 342, in start_server\n    process_exec_queue(interpreter)\n', '  File "/home/nimish/Downloads/pycharm-community-2017.3.2/helpers/pydev/pydevconsole.py", line 198, in process_exec_queue\n    more = interpreter.add_exec(code_fragment)\n', '  File "/home/nimish/Downloads/pycharm-community-2017.3.2/helpers/pydev/_pydev_bundle/pydev_console_utils.py", line 268, in add_exec\n    more = self.do_add_exec(code_fragment)\n', '  File "/home/nimish/Downloads/pycharm-community-2017.3.2/helpers/pydev/_pydev_bundle/pydev_ipython_console.py", line 41, in do_add_exec\n    res = bool(self.interpreter.add_exec(code_fragment.text))\n', '  File "/home/nimish/Downloads/pycharm-community-2017.3.2/helpers/pydev/_pydev_bundle/pydev_ipython_console_011.py", line 456, in add_exec\n    self.ipython.run_cell(line, store_history=True)\n', '  File "/home/nimish/anaconda3/envs/untitled3/lib/python3.5/site-packages/IPython/core/interactiveshell.py", line 2728, in run_cell\n    interactivity=interactivity, compiler=compiler, result=result)\n', '  File "/home/nimish/anaconda3/envs/untitled3/lib/python3.5/site-packages/IPython/core/interactiveshell.py", line 2850, in run_ast_nodes\n    if self.run_code(code, result):\n', '  File "/home/nimish/anaconda3/envs/untitled3/lib/python3.5/site-packages/IPython/core/interactiveshell.py", line 2910, in run_code\n    exec(code_obj, self.user_global_ns, self.user_ns)\n', '  File "<ipython-input-16-7ff71f6a5e64>", line 1, in <module>\n    result = k.get()\n', '  File "/home/nimish/anaconda3/envs/untitled3/lib/python3.5/site-packages/zcrmsdk/Operations.py", line 244, in get\n    return EntityAPIHandler.get_instance(self).get_record()\n', '  File "/home/nimish/anaconda3/envs/untitled3/lib/python3.5/site-packages/zcrmsdk/Handler.py", line 59, in get_record\n    apiResponse=APIRequest(handler_ins).get_api_response()\n', '  File "/home/nimish/anaconda3/envs/untitled3/lib/python3.5/site-packages/zcrmsdk/Request.py", line 58, in get_api_response\n    CommonUtil.raise_exception(self.url,ex.message,traceback.format_stack())\n']
